Workbook

Sheet Read Me
B2: Roundup Games — Non-Profit Financial Model
B3: 5-year projection · three scenarios · formula-driven · editable · headcount-driven personnel
B8: Purpose
B9: A discussion tool for collaborator / funder conversations about the viability of the non-profit organisation behind roundup.games.
B11: How to use
B12: 1) 'Headcount' sheet — edit FTE per role per year (yellow). Personnel cost is derived live via SUMPRODUCT(role cost × FTE) and feeds every model. 2) 'Assumptions' sheet — all other drivers (growth, prices, grants, space). 3) 'Model - Conservative / Base / Ambitious' — full 5-year P&L per scenario. 4) 'Summary' compares scenarios; 'Research & Benchmarks' sources every figure.
B14: Headcount model
B15: Personnel cost is NOT a flat number — it is built from a role × department × FTE matrix with DACH all-in salary costs (gross × ~1.22 employer overhead). 10 roles across 5 departments. Fractional FTE = part-time. Volunteer-leveraged: paid staff cover only accountability/continuity roles; events, library counter, moderation, translation are volunteer-staffed.
B17: Departments
B18: Engineering · Community & Operations · Partnerships & Fundraising · Programs (Library + Certification) · Finance & Admin. Finance/Admin stays OUTSOURCED (in the Legal line) until Base Y4 / Ambitious Y3, when an in-house hire becomes cheaper than external bookkeeping.
B20: The revenue streams
B21: 1) Commission on paid seats · 2) GM subscriptions · 3) Branded events · 4) Library of things · 5) Certification · 6) B2B events · 7) Grants & donations.
... B42: Planning estimates for discussion only — not audited, not a funding guarantee.

Sheet Headcount
A1: Headcount — role × department × FTE × all-in cost (drives Personnel)
A2: Personnel cost = SUMPRODUCT(cost × FTE) per scenario-year. Edit yellow FTE cells. Costs are DACH all-in (gross × ~1.22 Arbeitgeberanteil). | D2: Conservative | J2: Base | P2: Ambitious
A3: Role | B3: Department | C3: €/yr per 1.0 FTE | D3: Y1 | E3: Y2 | F3: Y3 | G3: Y4 | H3: Y5 | J3: Y1 | K3: Y2 | L3: Y3 | M3: Y4 | N3: Y5 | P3: Y1 | Q3: Y2 | R3: Y3 | S3: Y4 | T3: Y5
A5: Lead / Senior Engineer | B5: Engineering | C5: 90000 | D5: 0 | E5: 0 | F5: 0 | G5: 0.05 | H5: 0.1 | J5: 0.5 | K5: 1 | L5: 1 | M5: 1 | N5: 1 | P5: 0.5 | Q5: 1 | R5: 1 | S5: 1.5 | T5: 2
A6: Mid Engineer | B6: Engineering | C6: 65000 | D6: 0 | E6: 0 | F6: 0 | G6: 0 | H6: 0 | J6: 0 | K6: 0.5 | L6: 0.5 | M6: 0.5 | N6: 0.5 | P6: 0 | Q6: 0.5 | R6: 0.5 | S6: 1 | T6: 1
A7: Community Manager | B7: Community & Operations | C7: 50000 | D7: 0 | E7: 0 | F7: 0.05 | G7: 0.1 | H7: 0.15 | J7: 0.3 | K7: 0.4 | L7: 0.5 | M7: 0.7 | N7: 0.9 | P7: 0.5 | Q7: 0.5 | R7: 1 | S7: 1 | T7: 1
A8: HQ / Space Coordinator | B8: Community & Operations | C8: 42000 | D8: 0 | E8: 0 | F8: 0 | G8: 0 | H8: 0.15 | J8: 0.2 | K8: 0.3 | L8: 0.4 | M8: 0.5 | N8: 0.7 | P8: 0.2 | Q8: 0.5 | R8: 0.5 | S8: 1 | T8: 1
A9: Event Coordinator | B9: Community & Operations | C9: 45000 | D9: 0 | E9: 0 | F9: 0 | G9: 0 | H9: 0 | J9: 0 | K9: 0.1 | L9: 0.2 | M9: 0.3 | N9: 0.4 | P9: 0 | Q9: 0.1 | R9: 0.2 | S9: 0.5 | T9: 0.5
A10: Fundraising / Grants Lead | B10: Partnerships & Fundraising | C10: 60000 | D10: 0.1 | E10: 0.1 | F10: 0.15 | G10: 0.2 | H10: 0.25 | J10: 0.15 | K10: 0.25 | L10: 0.3 | M10: 0.3 | N10: 0.4 | P10: 0.15 | Q10: 0.25 | R10: 0.35 | S10: 0.5 | T10: 0.5
A11: Partnerships Manager | B11: Partnerships & Fundraising | C11: 60000 | D11: 0 | E11: 0 | F11: 0 | G11: 0 | H11: 0 | J11: 0 | K11: 0.1 | L11: 0.25 | M11: 0.35 | N11: 0.4 | P11: 0 | Q11: 0.2 | R11: 0.2 | S11: 0.4 | T11: 0.4
A12: Library Coordinator | B12: Programs | C12: 40000 | D12: 0 | E12: 0 | F12: 0 | G12: 0 | H12: 0 | J12: 0 | K12: 0.1 | L12: 0.15 | M12: 0.2 | N12: 0.3 | P12: 0 | Q12: 0.1 | R12: 0.2 | S12: 0.25 | T12: 0.4
A13: Certification Lead | B13: Programs | C13: 55000 | D13: 0 | E13: 0 | F13: 0 | G13: 0 | H13: 0 | J13: 0 | K13: 0.1 | L13: 0.2 | M13: 0.3 | N13: 0.4 | P13: 0 | Q13: 0.2 | R13: 0.4 | S13: 0.5 | T13: 0.7
A14: Finance / Office Manager | B14: Finance & Admin | C14: 45000 | D14: 0 | E14: 0 | F14: 0 | G14: 0 | H14: 0 | J14: 0 | K14: 0 | L14: 0 | M14: 0.1 | N14: 0.2 | P14: 0 | Q14: 0 | R14: 0 | S14: 0.1 | T14: 0.2
A15: Total personnel cost (EUR) | D15: =SUMPRODUCT($C$5:$C$14,D$5:D$14) | E15: =SUMPRODUCT($C$5:$C$14,E$5:E$14) | F15: =SUMPRODUCT($C$5:$C$14,F$5:F$14) | G15: =SUMPRODUCT($C$5:$C$14,G$5:G$14) | H15: =SUMPRODUCT($C$5:$C$14,H$5:H$14) | J15: =SUMPRODUCT($C$5:$C$14,J$5:J$14) | K15: =SUMPRODUCT($C$5:$C$14,K$5:K$14) | L15: =SUMPRODUCT($C$5:$C$14,L$5:L$14) | M15: =SUMPRODUCT($C$5:$C$14,M$5:M$14) | N15: =SUMPRODUCT($C$5:$C$14,N$5:N$14) | P15: =SUMPRODUCT($C$5:$C$14,P$5:P$14) | Q15: =SUMPRODUCT($C$5:$C$14,Q$5:Q$14) | R15: =SUMPRODUCT($C$5:$C$14,R$5:R$14) | S15: =SUMPRODUCT($C$5:$C$14,S$5:S$14) | T15: =SUMPRODUCT($C$5:$C$14,T$5:T$14)
A16: Total FTE | D16: =SUM(D5:D14) | E16: =SUM(E5:E14) | F16: =SUM(F5:F14) | G16: =SUM(G5:G14) | H16: =SUM(H5:H14) | J16: =SUM(J5:J14) | K16: =SUM(K5:K14) | L16: =SUM(L5:L14) | M16: =SUM(M5:M14) | N16: =SUM(N5:N14) | P16: =SUM(P5:P14) | Q16: =SUM(Q5:Q14) | R16: =SUM(R5:R14) | S16: =SUM(S5:S14) | T16: =SUM(T5:T14)
A18: Volunteer leverage (not in headcount)
A19: • Events: on-site setup/teardown, registration desk, game librarians at branded events — volunteer-staffed, overseen by the paid Event Coordinator (where present) or the Community Manager.
A20: • Library counter: lending/check-in at the HQ is volunteer-staffed (2–4 regulars per location), coordinated by the HQ/Space Coordinator. This is how Libraries of Things stay viable per the research.
A21: • Content: translation (EN/DE), community moderation backstop, documentation — volunteer-contributed.
A22: • Engineering: the platform is built; non-critical features and bug-fixes can take open-source-style volunteer contributions, reviewed by the paid Lead Engineer.
A23: • The paid roles above cover ONLY accountability/continuity: fundraising, finance/compliance, platform integrity, HQ operations, and (at scale) programme delivery.

Sheet Assumptions
A1: Assumptions — non-personnel drivers (yellow cells)
A2: Personnel lives on the Headcount sheet. Everything else is here. | D2: Conservative | J2: Base | P2: Ambitious
B3: Driver | C3: Unit | D3: Y1 | E3: Y2 | F3: Y3 | G3: Y4 | H3: Y5 | J3: Y1 | K3: Y2 | L3: Y3 | M3: Y4 | N3: Y5 | P3: Y1 | Q3: Y2 | R3: Y3 | S3: Y4 | T3: Y5
B4: Monthly active users | C4: users | D4: 300 | E4: 700 | F4: 1200 | G4: 2000 | H4: 3000 | J4: 1200 | K4: 3000 | L4: 8000 | M4: 21000 | N4: 50000 | P4: 3000 | Q4: 8000 | R4: 25000 | S4: 60000 | T4: 120000
B5: Paid seats sold | C5: seats/yr | D5: 150 | E5: 400 | F5: 900 | G5: 1600 | H5: 2500 | J5: 800 | K5: 2500 | L5: 6500 | M5: 14000 | N5: 27000 | P5: 2500 | Q5: 7000 | R5: 20000 | S5: 38000 | T5: 75000
B6: Average seat price | C6: EUR | D6: 16 | E6: 16 | F6: 17 | G6: 17 | H6: 18 | J6: 18 | K6: 19 | L6: 20 | M6: 21 | N6: 22 | P6: 18 | Q6: 19 | R6: 21 | S6: 22 | T6: 24
B7: Commission take rate | C7: % | D7: 0.06 | E7: 0.06 | F7: 0.07 | G7: 0.07 | H7: 0.08 | J7: 0.09 | K7: 0.1 | L7: 0.11 | M7: 0.12 | N7: 0.13 | P7: 0.08 | Q7: 0.09 | R7: 0.1 | S7: 0.1 | T7: 0.11
B8: Paying GMs (avg in year) | C8: GMs | D8: 5 | E8: 12 | F8: 22 | G8: 35 | H8: 55 | J8: 15 | K8: 45 | L8: 90 | M8: 160 | N8: 260 | P8: 40 | Q8: 110 | R8: 230 | S8: 420 | T8: 700
B9: GM subscription price | C9: EUR/mo | D9: 7.99 | E9: 7.99 | F9: 8.99 | G9: 8.99 | H9: 9.99 | J9: 10.99 | K9: 11.99 | L9: 12.99 | M9: 13.99 | N9: 14.99 | P9: 9.99 | Q9: 10.99 | R9: 11.99 | S9: 12.99 | T9: 13.99
B10: Branded events | C10: events | D10: 0 | E10: 1 | F10: 1 | G10: 2 | H10: 2 | J10: 1 | K10: 2 | L10: 4 | M10: 8 | N10: 16 | P10: 2 | Q10: 4 | R10: 8 | S10: 16 | T10: 32
B11: Avg attendance per event | C11: people | D11: 0 | E11: 50 | F11: 70 | G11: 100 | H11: 120 | J11: 80 | K11: 120 | L11: 180 | M11: 250 | N11: 350 | P11: 100 | Q11: 180 | R11: 300 | S11: 450 | T11: 600
B12: Event ticket price | C12: EUR | D12: 0 | E12: 12 | F12: 14 | G12: 15 | H12: 16 | J12: 15 | K12: 18 | L12: 22 | M12: 25 | N12: 28 | P12: 16 | Q12: 20 | R12: 25 | S12: 28 | T12: 32
B13: Event cost per attendee | C13: EUR | D13: 0 | E13: 9 | F13: 10 | G13: 10 | H13: 10 | J13: 11 | K13: 12 | L13: 14 | M13: 15 | N13: 16 | P13: 11 | Q13: 12 | R13: 14 | S13: 15 | T13: 16
B14: Library-tier members | C14: members | D14: 0 | E14: 20 | F14: 35 | G14: 55 | H14: 80 | J14: 30 | K14: 80 | L14: 150 | M14: 250 | N14: 380 | P14: 60 | Q14: 160 | R14: 320 | S14: 550 | T14: 850
B15: Library tier fee | C15: EUR/mo | D15: 3.99 | E15: 3.99 | F15: 4.49 | G15: 4.49 | H15: 4.99 | J15: 4.99 | K15: 5.49 | L15: 5.99 | M15: 6.49 | N15: 6.99 | P15: 5.99 | Q15: 6.49 | R15: 6.99 | S15: 7.49 | T15: 7.99
... B37: Payment processing rate | C37: % | D37: 0.035 | E37: 0.035 | F37: 0.035 | G37: 0.035 | H37: 0.035 | J37: 0.035 | K37: 0.035 | L37: 0.035 | M37: 0.032 | N37: 0.03 | P37: 0.035 | Q37: 0.032 | R37: 0.03 | S37: 0.028 | T37: 0.025

Sheet Model - Conservative
A1: Model — Conservative (lean volunteer, DACH-only)
A2: Personnel from 'Headcount'; all else from 'Assumptions'.
A4: EUR / year | B4: Year 1 | C4: Year 2 | D4: Year 3 | E4: Year 4 | F4: Year 5
A5: REVENUE
A6: Commission on paid seats | B6: ='Assumptions'!D5*'Assumptions'!D6*'Assumptions'!D7 | C6: ='Assumptions'!E5*'Assumptions'!E6*'Assumptions'!E7 | D6: ='Assumptions'!F5*'Assumptions'!F6*'Assumptions'!F7 | E6: ='Assumptions'!G5*'Assumptions'!G6*'Assumptions'!G7 | F6: ='Assumptions'!H5*'Assumptions'!H6*'Assumptions'!H7
A7: GM membership subscriptions | B7: ='Assumptions'!D8*'Assumptions'!D9*12 | C7: ='Assumptions'!E8*'Assumptions'!E9*12 | D7: ='Assumptions'!F8*'Assumptions'!F9*12 | E7: ='Assumptions'!G8*'Assumptions'!G9*12 | F7: ='Assumptions'!H8*'Assumptions'!H9*12
A8: Branded events (gross) | B8: ='Assumptions'!D10*'Assumptions'!D11*'Assumptions'!D12 | C8: ='Assumptions'!E10*'Assumptions'!E11*'Assumptions'!E12 | D8: ='Assumptions'!F10*'Assumptions'!F11*'Assumptions'!F12 | E8: ='Assumptions'!G10*'Assumptions'!G11*'Assumptions'!G12 | F8: ='Assumptions'!H10*'Assumptions'!H11*'Assumptions'!H12
A9: Library of things (borrowing tier) | B9: ='Assumptions'!D14*'Assumptions'!D15*12 | C9: ='Assumptions'!E14*'Assumptions'!E15*12 | D9: ='Assumptions'!F14*'Assumptions'!F15*12 | E9: ='Assumptions'!G14*'Assumptions'!G15*12 | F9: ='Assumptions'!H14*'Assumptions'!H15*12
A10: Certification program fees | B10: ='Assumptions'!D18*'Assumptions'!D19 | C10: ='Assumptions'!E18*'Assumptions'!E19 | D10: ='Assumptions'!F18*'Assumptions'!F19 | E10: ='Assumptions'!G18*'Assumptions'!G19 | F10: ='Assumptions'!H18*'Assumptions'!H19
A11: B2B events (commission) | B11: ='Assumptions'!D22*'Assumptions'!D23*'Assumptions'!D24*'Assumptions'!D25 | C11: ='Assumptions'!E22*'Assumptions'!E23*'Assumptions'!E24*'Assumptions'!E25 | D11: ='Assumptions'!F22*'Assumptions'!F23*'Assumptions'!F24*'Assumptions'!F25 | E11: ='Assumptions'!G22*'Assumptions'!G23*'Assumptions'!G24*'Assumptions'!G25 | F11: ='Assumptions'!H22*'Assumptions'!H23*'Assumptions'!H24*'Assumptions'!H25
A12: Grants | B12: ='Assumptions'!D26 | C12: ='Assumptions'!E26 | D12: ='Assumptions'!F26 | E12: ='Assumptions'!G26 | F12: ='Assumptions'!H26
A13: Donations (recurring + one-off) | B13: ='Assumptions'!D27*'Assumptions'!D28+'Assumptions'!D29 | C13: ='Assumptions'!E27*'Assumptions'!E28+'Assumptions'!E29 | D13: ='Assumptions'!F27*'Assumptions'!F28+'Assumptions'!F29 | E13: ='Assumptions'!G27*'Assumptions'!G28+'Assumptions'!G29 | F13: ='Assumptions'!H27*'Assumptions'!H28+'Assumptions'!H29
A14: Working-capital bridge (capacity grant / founder loan) | B14: ='Assumptions'!D30 | C14: ='Assumptions'!E30 | D14: ='Assumptions'!F30 | E14: ='Assumptions'!G30 | F14: ='Assumptions'!H30
A15: Total revenue | B15: =SUM(B6:B14) | C15: =SUM(C6:C14) | D15: =SUM(D6:D14) | E15: =SUM(E6:E14) | F15: =SUM(F6:F14)
A17: DIRECT COSTS
A18: Payment processing fees | B18: ='Assumptions'!D37*(B6+B7+B8+B9+B10+B11) | C18: ='Assumptions'!E37*(C6+C7+C8+C9+C10+C11) | D18: ='Assumptions'!F37*(D6+D7+D8+D9+D10+D11) | E18: ='Assumptions'!G37*(E6+E7+E8+E9+E10+E11) | F18: ='Assumptions'!H37*(F6+F7+F8+F9+F10+F11)
A19: Event COGS (venue / catering / swag) | B19: ='Assumptions'!D10*'Assumptions'!D11*'Assumptions'!D13 | C19: ='Assumptions'!E10*'Assumptions'!E11*'Assumptions'!E13 | D19: ='Assumptions'!F10*'Assumptions'!F11*'Assumptions'!F13 | E19: ='Assumptions'!G10*'Assumptions'!G11*'Assumptions'!G13 | F19: ='Assumptions'!H10*'Assumptions'!H11*'Assumptions'!H13
A20: Library shrinkage & replenishment | B20: ='Assumptions'!D16 | C20: ='Assumptions'!E16 | D20: ='Assumptions'!F16 | E20: ='Assumptions'!G16 | F20: ='Assumptions'!H16
A21: Certification ops (assessment + curriculum) | B21: ='Assumptions'!D20+'Assumptions'!D18*'Assumptions'!D21 | C21: ='Assumptions'!E20+'Assumptions'!E18*'Assumptions'!E21 | D21: ='Assumptions'!F20+'Assumptions'!F18*'Assumptions'!F21 | E21: ='Assumptions'!G20+'Assumptions'!G18*'Assumptions'!G21 | F21: ='Assumptions'!H20+'Assumptions'!H18*'Assumptions'!H21
A22: Total direct costs | B22: =SUM(B18:B21) | C22: =SUM(C18:C21) | D22: =SUM(D18:D21) | E22: =SUM(E18:E21) | F22: =SUM(F18:F21)
A23: Gross contribution | B23: =B15-B22 | C23: =C15-C22 | D23: =D15-D22 | E23: =E15-E22 | F23: =F15-F22
A25: OPERATING COSTS
A26: Infrastructure & hosting | B26: ='Assumptions'!D34*12 | C26: ='Assumptions'!E34*12 | D26: ='Assumptions'!F34*12 | E26: ='Assumptions'!G34*12 | F26: ='Assumptions'!H34*12
A27: Community HQ (rent + utils + fit-out) | B27: ='Assumptions'!D31*'Assumptions'!D32*12+'Assumptions'!D33 | C27: ='Assumptions'!E31*'Assumptions'!E32*12+'Assumptions'!E33 | D27: ='Assumptions'!F31*'Assumptions'!F32*12+'Assumptions'!F33 | E27: ='Assumptions'!G31*'Assumptions'!G32*12+'Assumptions'!G33 | F27: ='Assumptions'!H31*'Assumptions'!H32*12+'Assumptions'!H33
A28: Library inventory (partnership-sourced) | B28: ='Assumptions'!D17 | C28: ='Assumptions'!E17 | D28: ='Assumptions'!F17 | E28: ='Assumptions'!G17 | F28: ='Assumptions'!H17
A29: Personnel (from Headcount sheet) | B29: ='Headcount'!D15 | C29: ='Headcount'!E15 | D29: ='Headcount'!F15 | E29: ='Headcount'!G15 | F29: ='Headcount'!H15
A30: Legal / admin / accounting (outsourced) | B30: ='Assumptions'!D35 | C30: ='Assumptions'!E35 | D30: ='Assumptions'!F35 | E30: ='Assumptions'!G35 | F30: ='Assumptions'!H35
A31: Marketing & community | B31: ='Assumptions'!D36 | C31: ='Assumptions'!E36 | D31: ='Assumptions'!F36 | E31: ='Assumptions'!G36 | F31: ='Assumptions'!H36
A32: Total operating costs | B32: =SUM(B26:B31) | C32: =SUM(C26:C31) | D32: =SUM(D26:D31) | E32: =SUM(E26:E31) | F32: =SUM(F26:F31)
A33: Operating result | B33: =B23-B32 | C33: =C23-C32 | D33: =D23-D32 | E33: =E23-E32 | F33: =F23-F32
A35: Tax provision (illustrative, gemeinnützig) | B35: =MAX(0,(B6+B7+B8+B9+B10+B11-B18-B19-B20-B21-45000))*0.15 | C35: =MAX(0,(C6+C7+C8+C9+C10+C11-C18-C19-C20-C21-45000))*0.15 | D35: =MAX(0,(D6+D7+D8+D9+D10+D11-D18-D19-D20-D21-45000))*0.15 | E35: =MAX(0,(E6+E7+E8+E9+E10+E11-E18-E19-E20-E21-45000))*0.15 | F35: =MAX(0,(F6+F7+F8+F9+F10+F11-F18-F19-F20-F21-45000))*0.15
A36: Net surplus / (deficit) | B36: =B33-B35 | C36: =C33-C35 | D36: =D33-D35 | E36: =E33-E35 | F36: =F33-F35
A37: Cumulative surplus / (deficit) | B37: =B36 | C37: =B37+C36 | D37: =C37+D36 | E37: =D37+E36 | F37: =E37+F36
A39: MEMO
A40: Mission-funding reliance (grants+donations) | B40: =(B12+B13)/B15 | C40: =(C12+C13)/C15 | D40: =(D12+D13)/D15 | E40: =(E12+E13)/E15 | F40: =(F12+F13)/F15
A41: Commercial revenue (all earned streams) | B41: =B6+B7+B8+B9+B10+B11 | C41: =C6+C7+C8+C9+C10+C11 | D41: =D6+D7+D8+D9+D10+D11 | E41: =E6+E7+E8+E9+E10+E11 | F41: =F6+F7+F8+F9+F10+F11
A42: New-initiative revenue (lib+cert+B2B) | B42: =B9+B10+B11 | C42: =C9+C10+C11 | D42: =D9+D10+D11 | E42: =E9+E10+E11 | F42: =F9+F10+F11
A43: New-initiative cost (space+inv+lib+cert ops) | B43: =B27+B28+B20+B21 | C43: =C27+C28+C20+C21 | D43: =D27+D28+D20+D21 | E43: =E27+E28+E20+E21 | F43: =F27+F28+F20+F21
A44: Total FTE (from Headcount) | B44: ='Headcount'!D16 | C44: ='Headcount'!E16 | D44: ='Headcount'!F16 | E44: ='Headcount'!G16 | F44: ='Headcount'!H16
A45: Personnel as % of revenue | B45: =B29/B15 | C45: =C29/C15 | D45: =D29/D15 | E45: =E29/E15 | F45: =F29/F15
...

Sheet Model - Base
A1: Model — Base (steady regional platform, DACH core)
A2: Personnel from 'Headcount'; all else from 'Assumptions'.
A4: EUR / year | B4: Year 1 | C4: Year 2 | D4: Year 3 | E4: Year 4 | F4: Year 5
A5: REVENUE
A6: Commission on paid seats | B6: ='Assumptions'!J5*'Assumptions'!J6*'Assumptions'!J7 | C6: ='Assumptions'!K5*'Assumptions'!K6*'Assumptions'!K7 | D6: ='Assumptions'!L5*'Assumptions'!L6*'Assumptions'!L7 | E6: ='Assumptions'!M5*'Assumptions'!M6*'Assumptions'!M7 | F6: ='Assumptions'!N5*'Assumptions'!N6*'Assumptions'!N7
A7: GM membership subscriptions | B7: ='Assumptions'!J8*'Assumptions'!J9*12 | C7: ='Assumptions'!K8*'Assumptions'!K9*12 | D7: ='Assumptions'!L8*'Assumptions'!L9*12 | E7: ='Assumptions'!M8*'Assumptions'!M9*12 | F7: ='Assumptions'!N8*'Assumptions'!N9*12
A8: Branded events (gross) | B8: ='Assumptions'!J10*'Assumptions'!J11*'Assumptions'!J12 | C8: ='Assumptions'!K10*'Assumptions'!K11*'Assumptions'!K12 | D8: ='Assumptions'!L10*'Assumptions'!L11*'Assumptions'!L12 | E8: ='Assumptions'!M10*'Assumptions'!M11*'Assumptions'!M12 | F8: ='Assumptions'!N10*'Assumptions'!N11*'Assumptions'!N12
A9: Library of things (borrowing tier) | B9: ='Assumptions'!J14*'Assumptions'!J15*12 | C9: ='Assumptions'!K14*'Assumptions'!K15*12 | D9: ='Assumptions'!L14*'Assumptions'!L15*12 | E9: ='Assumptions'!M14*'Assumptions'!M15*12 | F9: ='Assumptions'!N14*'Assumptions'!N15*12
A10: Certification program fees | B10: ='Assumptions'!J18*'Assumptions'!J19 | C10: ='Assumptions'!K18*'Assumptions'!K19 | D10: ='Assumptions'!L18*'Assumptions'!L19 | E10: ='Assumptions'!M18*'Assumptions'!M19 | F10: ='Assumptions'!N18*'Assumptions'!N19
A11: B2B events (commission) | B11: ='Assumptions'!J22*'Assumptions'!J23*'Assumptions'!J24*'Assumptions'!J25 | C11: ='Assumptions'!K22*'Assumptions'!K23*'Assumptions'!K24*'Assumptions'!K25 | D11: ='Assumptions'!L22*'Assumptions'!L23*'Assumptions'!L24*'Assumptions'!L25 | E11: ='Assumptions'!M22*'Assumptions'!M23*'Assumptions'!M24*'Assumptions'!M25 | F11: ='Assumptions'!N22*'Assumptions'!N23*'Assumptions'!N24*'Assumptions'!N25
A12: Grants | B12: ='Assumptions'!J26 | C12: ='Assumptions'!K26 | D12: ='Assumptions'!L26 | E12: ='Assumptions'!M26 | F12: ='Assumptions'!N26
A13: Donations (recurring + one-off) | B13: ='Assumptions'!J27*'Assumptions'!J28+'Assumptions'!J29 | C13: ='Assumptions'!K27*'Assumptions'!K28+'Assumptions'!K29 | D13: ='Assumptions'!L27*'Assumptions'!L28+'Assumptions'!L29 | E13: ='Assumptions'!M27*'Assumptions'!M28+'Assumptions'!M29 | F13: ='Assumptions'!N27*'Assumptions'!N28+'Assumptions'!N29
A14: Working-capital bridge (capacity grant / founder loan) | B14: ='Assumptions'!J30 | C14: ='Assumptions'!K30 | D14: ='Assumptions'!L30 | E14: ='Assumptions'!M30 | F14: ='Assumptions'!N30
A15: Total revenue | B15: =SUM(B6:B14) | C15: =SUM(C6:C14) | D15: =SUM(D6:D14) | E15: =SUM(E6:E14) | F15: =SUM(F6:F14)
A17: DIRECT COSTS
A18: Payment processing fees | B18: ='Assumptions'!J37*(B6+B7+B8+B9+B10+B11) | C18: ='Assumptions'!K37*(C6+C7+C8+C9+C10+C11) | D18: ='Assumptions'!L37*(D6+D7+D8+D9+D10+D11) | E18: ='Assumptions'!M37*(E6+E7+E8+E9+E10+E11) | F18: ='Assumptions'!N37*(F6+F7+F8+F9+F10+F11)
A19: Event COGS (venue / catering / swag) | B19: ='Assumptions'!J10*'Assumptions'!J11*'Assumptions'!J13 | C19: ='Assumptions'!K10*'Assumptions'!K11*'Assumptions'!K13 | D19: ='Assumptions'!L10*'Assumptions'!L11*'Assumptions'!L13 | E19: ='Assumptions'!M10*'Assumptions'!M11*'Assumptions'!M13 | F19: ='Assumptions'!N10*'Assumptions'!N11*'Assumptions'!N13
A20: Library shrinkage & replenishment | B20: ='Assumptions'!J16 | C20: ='Assumptions'!K16 | D20: ='Assumptions'!L16 | E20: ='Assumptions'!M16 | F20: ='Assumptions'!N16
A21: Certification ops (assessment + curriculum) | B21: ='Assumptions'!J20+'Assumptions'!J18*'Assumptions'!J21 | C21: ='Assumptions'!K20+'Assumptions'!K18*'Assumptions'!K21 | D21: ='Assumptions'!L20+'Assumptions'!L18*'Assumptions'!L21 | E21: ='Assumptions'!M20+'Assumptions'!M18*'Assumptions'!M21 | F21: ='Assumptions'!N20+'Assumptions'!N18*'Assumptions'!N21
A22: Total direct costs | B22: =SUM(B18:B21) | C22: =SUM(C18:C21) | D22: =SUM(D18:D21) | E22: =SUM(E18:E21) | F22: =SUM(F18:F21)
A23: Gross contribution | B23: =B15-B22 | C23: =C15-C22 | D23: =D15-D22 | E23: =E15-E22 | F23: =F15-F22
A25: OPERATING COSTS
A26: Infrastructure & hosting | B26: ='Assumptions'!J34*12 | C26: ='Assumptions'!K34*12 | D26: ='Assumptions'!L34*12 | E26: ='Assumptions'!M34*12 | F26: ='Assumptions'!N34*12
A27: Community HQ (rent + utils + fit-out) | B27: ='Assumptions'!J31*'Assumptions'!J32*12+'Assumptions'!J33 | C27: ='Assumptions'!K31*'Assumptions'!K32*12+'Assumptions'!K33 | D27: ='Assumptions'!L31*'Assumptions'!L32*12+'Assumptions'!L33 | E27: ='Assumptions'!M31*'Assumptions'!M32*12+'Assumptions'!M33 | F27: ='Assumptions'!N31*'Assumptions'!N32*12+'Assumptions'!N33
A28: Library inventory (partnership-sourced) | B28: ='Assumptions'!J17 | C28: ='Assumptions'!K17 | D28: ='Assumptions'!L17 | E28: ='Assumptions'!M17 | F28: ='Assumptions'!N17
A29: Personnel (from Headcount sheet) | B29: ='Headcount'!J15 | C29: ='Headcount'!K15 | D29: ='Headcount'!L15 | E29: ='Headcount'!M15 | F29: ='Headcount'!N15
A30: Legal / admin / accounting (outsourced) | B30: ='Assumptions'!J35 | C30: ='Assumptions'!K35 | D30: ='Assumptions'!L35 | E30: ='Assumptions'!M35 | F30: ='Assumptions'!N35
A31: Marketing & community | B31: ='Assumptions'!J36 | C31: ='Assumptions'!K36 | D31: ='Assumptions'!L36 | E31: ='Assumptions'!M36 | F31: ='Assumptions'!N36
A32: Total operating costs | B32: =SUM(B26:B31) | C32: =SUM(C26:C31) | D32: =SUM(D26:D31) | E32: =SUM(E26:E31) | F32: =SUM(F26:F31)
A33: Operating result | B33: =B23-B32 | C33: =C23-C32 | D33: =D23-D32 | E33: =E23-E32 | F33: =F23-F32
A35: Tax provision (illustrative, gemeinnützig) | B35: =MAX(0,(B6+B7+B8+B9+B10+B11-B18-B19-B20-B21-45000))*0.15 | C35: =MAX(0,(C6+C7+C8+C9+C10+C11-C18-C19-C20-C21-45000))*0.15 | D35: =MAX(0,(D6+D7+D8+D9+D10+D11-D18-D19-D20-D21-45000))*0.15 | E35: =MAX(0,(E6+E7+E8+E9+E10+E11-E18-E19-E20-E21-45000))*0.15 | F35: =MAX(0,(F6+F7+F8+F9+F10+F11-F18-F19-F20-F21-45000))*0.15
A36: Net surplus / (deficit) | B36: =B33-B35 | C36: =C33-C35 | D36: =D33-D35 | E36: =E33-E35 | F36: =F33-F35
A37: Cumulative surplus / (deficit) | B37: =B36 | C37: =B37+C36 | D37: =C37+D36 | E37: =D37+E36 | F37: =E37+F36
A39: MEMO
A40: Mission-funding reliance (grants+donations) | B40: =(B12+B13)/B15 | C40: =(C12+C13)/C15 | D40: =(D12+D13)/D15 | E40: =(E12+E13)/E15 | F40: =(F12+F13)/F15
A41: Commercial revenue (all earned streams) | B41: =B6+B7+B8+B9+B10+B11 | C41: =C6+C7+C8+C9+C10+C11 | D41: =D6+D7+D8+D9+D10+D11 | E41: =E6+E7+E8+E9+E10+E11 | F41: =F6+F7+F8+F9+F10+F11
A42: New-initiative revenue (lib+cert+B2B) | B42: =B9+B10+B11 | C42: =C9+C10+C11 | D42: =D9+D10+D11 | E42: =E9+E10+E11 | F42: =F9+F10+F11
A43: New-initiative cost (space+inv+lib+cert ops) | B43: =B27+B28+B20+B21 | C43: =C27+C28+C20+C21 | D43: =D27+D28+D20+D21 | E43: =E27+E28+E20+E21 | F43: =F27+F28+F20+F21
A44: Total FTE (from Headcount) | B44: ='Headcount'!J16 | C44: ='Headcount'!K16 | D44: ='Headcount'!L16 | E44: ='Headcount'!M16 | F44: ='Headcount'!N16
A45: Personnel as % of revenue | B45: =B29/B15 | C45: =C29/C15 | D45: =D29/D15 | E45: =E29/E15 | F45: =F29/F15
...

Sheet Model - Ambitious
A1: Model — Ambitious (pan-European, staffed org)
A2: Personnel from 'Headcount'; all else from 'Assumptions'.
A4: EUR / year | B4: Year 1 | C4: Year 2 | D4: Year 3 | E4: Year 4 | F4: Year 5
A5: REVENUE
A6: Commission on paid seats | B6: ='Assumptions'!P5*'Assumptions'!P6*'Assumptions'!P7 | C6: ='Assumptions'!Q5*'Assumptions'!Q6*'Assumptions'!Q7 | D6: ='Assumptions'!R5*'Assumptions'!R6*'Assumptions'!R7 | E6: ='Assumptions'!S5*'Assumptions'!S6*'Assumptions'!S7 | F6: ='Assumptions'!T5*'Assumptions'!T6*'Assumptions'!T7
A7: GM membership subscriptions | B7: ='Assumptions'!P8*'Assumptions'!P9*12 | C7: ='Assumptions'!Q8*'Assumptions'!Q9*12 | D7: ='Assumptions'!R8*'Assumptions'!R9*12 | E7: ='Assumptions'!S8*'Assumptions'!S9*12 | F7: ='Assumptions'!T8*'Assumptions'!T9*12
A8: Branded events (gross) | B8: ='Assumptions'!P10*'Assumptions'!P11*'Assumptions'!P12 | C8: ='Assumptions'!Q10*'Assumptions'!Q11*'Assumptions'!Q12 | D8: ='Assumptions'!R10*'Assumptions'!R11*'Assumptions'!R12 | E8: ='Assumptions'!S10*'Assumptions'!S11*'Assumptions'!S12 | F8: ='Assumptions'!T10*'Assumptions'!T11*'Assumptions'!T12
A9: Library of things (borrowing tier) | B9: ='Assumptions'!P14*'Assumptions'!P15*12 | C9: ='Assumptions'!Q14*'Assumptions'!Q15*12 | D9: ='Assumptions'!R14*'Assumptions'!R15*12 | E9: ='Assumptions'!S14*'Assumptions'!S15*12 | F9: ='Assumptions'!T14*'Assumptions'!T15*12
A10: Certification program fees | B10: ='Assumptions'!P18*'Assumptions'!P19 | C10: ='Assumptions'!Q18*'Assumptions'!Q19 | D10: ='Assumptions'!R18*'Assumptions'!R19 | E10: ='Assumptions'!S18*'Assumptions'!S19 | F10: ='Assumptions'!T18*'Assumptions'!T19
A11: B2B events (commission) | B11: ='Assumptions'!P22*'Assumptions'!P23*'Assumptions'!P24*'Assumptions'!P25 | C11: ='Assumptions'!Q22*'Assumptions'!Q23*'Assumptions'!Q24*'Assumptions'!Q25 | D11: ='Assumptions'!R22*'Assumptions'!R23*'Assumptions'!R24*'Assumptions'!R25 | E11: ='Assumptions'!S22*'Assumptions'!S23*'Assumptions'!S24*'Assumptions'!S25 | F11: ='Assumptions'!T22*'Assumptions'!T23*'Assumptions'!T24*'Assumptions'!T25
A12: Grants | B12: ='Assumptions'!P26 | C12: ='Assumptions'!Q26 | D12: ='Assumptions'!R26 | E12: ='Assumptions'!S26 | F12: ='Assumptions'!T26
A13: Donations (recurring + one-off) | B13: ='Assumptions'!P27*'Assumptions'!P28+'Assumptions'!P29 | C13: ='Assumptions'!Q27*'Assumptions'!Q28+'Assumptions'!Q29 | D13: ='Assumptions'!R27*'Assumptions'!R28+'Assumptions'!R29 | E13: ='Assumptions'!S27*'Assumptions'!S28+'Assumptions'!S29 | F13: ='Assumptions'!T27*'Assumptions'!T28+'Assumptions'!T29
A14: Working-capital bridge (capacity grant / founder loan) | B14: ='Assumptions'!P30 | C14: ='Assumptions'!Q30 | D14: ='Assumptions'!R30 | E14: ='Assumptions'!S30 | F14: ='Assumptions'!T30
A15: Total revenue | B15: =SUM(B6:B14) | C15: =SUM(C6:C14) | D15: =SUM(D6:D14) | E15: =SUM(E6:E14) | F15: =SUM(F6:F14)
A17: DIRECT COSTS
A18: Payment processing fees | B18: ='Assumptions'!P37*(B6+B7+B8+B9+B10+B11) | C18: ='Assumptions'!Q37*(C6+C7+C8+C9+C10+C11) | D18: ='Assumptions'!R37*(D6+D7+D8+D9+D10+D11) | E18: ='Assumptions'!S37*(E6+E7+E8+E9+E10+E11) | F18: ='Assumptions'!T37*(F6+F7+F8+F9+F10+F11)
A19: Event COGS (venue / catering / swag) | B19: ='Assumptions'!P10*'Assumptions'!P11*'Assumptions'!P13 | C19: ='Assumptions'!Q10*'Assumptions'!Q11*'Assumptions'!Q13 | D19: ='Assumptions'!R10*'Assumptions'!R11*'Assumptions'!R13 | E19: ='Assumptions'!S10*'Assumptions'!S11*'Assumptions'!S13 | F19: ='Assumptions'!T10*'Assumptions'!T11*'Assumptions'!T13
A20: Library shrinkage & replenishment | B20: ='Assumptions'!P16 | C20: ='Assumptions'!Q16 | D20: ='Assumptions'!R16 | E20: ='Assumptions'!S16 | F20: ='Assumptions'!T16
A21: Certification ops (assessment + curriculum) | B21: ='Assumptions'!P20+'Assumptions'!P18*'Assumptions'!P21 | C21: ='Assumptions'!Q20+'Assumptions'!Q18*'Assumptions'!Q21 | D21: ='Assumptions'!R20+'Assumptions'!R18*'Assumptions'!R21 | E21: ='Assumptions'!S20+'Assumptions'!S18*'Assumptions'!S21 | F21: ='Assumptions'!T20+'Assumptions'!T18*'Assumptions'!T21
A22: Total direct costs | B22: =SUM(B18:B21) | C22: =SUM(C18:C21) | D22: =SUM(D18:D21) | E22: =SUM(E18:E21) | F22: =SUM(F18:F21)
A23: Gross contribution | B23: =B15-B22 | C23: =C15-C22 | D23: =D15-D22 | E23: =E15-E22 | F23: =F15-F22
A25: OPERATING COSTS
A26: Infrastructure & hosting | B26: ='Assumptions'!P34*12 | C26: ='Assumptions'!Q34*12 | D26: ='Assumptions'!R34*12 | E26: ='Assumptions'!S34*12 | F26: ='Assumptions'!T34*12
A27: Community HQ (rent + utils + fit-out) | B27: ='Assumptions'!P31*'Assumptions'!P32*12+'Assumptions'!P33 | C27: ='Assumptions'!Q31*'Assumptions'!Q32*12+'Assumptions'!Q33 | D27: ='Assumptions'!R31*'Assumptions'!R32*12+'Assumptions'!R33 | E27: ='Assumptions'!S31*'Assumptions'!S32*12+'Assumptions'!S33 | F27: ='Assumptions'!T31*'Assumptions'!T32*12+'Assumptions'!T33
A28: Library inventory (partnership-sourced) | B28: ='Assumptions'!P17 | C28: ='Assumptions'!Q17 | D28: ='Assumptions'!R17 | E28: ='Assumptions'!S17 | F28: ='Assumptions'!T17
A29: Personnel (from Headcount sheet) | B29: ='Headcount'!P15 | C29: ='Headcount'!Q15 | D29: ='Headcount'!R15 | E29: ='Headcount'!S15 | F29: ='Headcount'!T15
A30: Legal / admin / accounting (outsourced) | B30: ='Assumptions'!P35 | C30: ='Assumptions'!Q35 | D30: ='Assumptions'!R35 | E30: ='Assumptions'!S35 | F30: ='Assumptions'!T35
A31: Marketing & community | B31: ='Assumptions'!P36 | C31: ='Assumptions'!Q36 | D31: ='Assumptions'!R36 | E31: ='Assumptions'!S36 | F31: ='Assumptions'!T36
A32: Total operating costs | B32: =SUM(B26:B31) | C32: =SUM(C26:C31) | D32: =SUM(D26:D31) | E32: =SUM(E26:E31) | F32: =SUM(F26:F31)
A33: Operating result | B33: =B23-B32 | C33: =C23-C32 | D33: =D23-D32 | E33: =E23-E32 | F33: =F23-F32
A35: Tax provision (illustrative, gemeinnützig) | B35: =MAX(0,(B6+B7+B8+B9+B10+B11-B18-B19-B20-B21-45000))*0.15 | C35: =MAX(0,(C6+C7+C8+C9+C10+C11-C18-C19-C20-C21-45000))*0.15 | D35: =MAX(0,(D6+D7+D8+D9+D10+D11-D18-D19-D20-D21-45000))*0.15 | E35: =MAX(0,(E6+E7+E8+E9+E10+E11-E18-E19-E20-E21-45000))*0.15 | F35: =MAX(0,(F6+F7+F8+F9+F10+F11-F18-F19-F20-F21-45000))*0.15
A36: Net surplus / (deficit) | B36: =B33-B35 | C36: =C33-C35 | D36: =D33-D35 | E36: =E33-E35 | F36: =F33-F35
A37: Cumulative surplus / (deficit) | B37: =B36 | C37: =B37+C36 | D37: =C37+D36 | E37: =D37+E36 | F37: =E37+F36
A39: MEMO
A40: Mission-funding reliance (grants+donations) | B40: =(B12+B13)/B15 | C40: =(C12+C13)/C15 | D40: =(D12+D13)/D15 | E40: =(E12+E13)/E15 | F40: =(F12+F13)/F15
A41: Commercial revenue (all earned streams) | B41: =B6+B7+B8+B9+B10+B11 | C41: =C6+C7+C8+C9+C10+C11 | D41: =D6+D7+D8+D9+D10+D11 | E41: =E6+E7+E8+E9+E10+E11 | F41: =F6+F7+F8+F9+F10+F11
A42: New-initiative revenue (lib+cert+B2B) | B42: =B9+B10+B11 | C42: =C9+C10+C11 | D42: =D9+D10+D11 | E42: =E9+E10+E11 | F42: =F9+F10+F11
A43: New-initiative cost (space+inv+lib+cert ops) | B43: =B27+B28+B20+B21 | C43: =C27+C28+C20+C21 | D43: =D27+D28+D20+D21 | E43: =E27+E28+E20+E21 | F43: =F27+F28+F20+F21
A44: Total FTE (from Headcount) | B44: ='Headcount'!P16 | C44: ='Headcount'!Q16 | D44: ='Headcount'!R16 | E44: ='Headcount'!S16 | F44: ='Headcount'!T16
A45: Personnel as % of revenue | B45: =B29/B15 | C45: =C29/C15 | D45: =D29/D15 | E45: =E29/E15 | F45: =F29/F15
...

Sheet Summary
A1: Summary — three scenarios compared
A2: All figures pulled live from the model + headcount sheets.
B3: Conservative | H3: Base | N3: Ambitious
A4: Metric | B4: Y1 | C4: Y2 | D4: Y3 | E4: Y4 | F4: Y5 | H4: Y1 | I4: Y2 | J4: Y3 | K4: Y4 | L4: Y5 | N4: Y1 | O4: Y2 | P4: Y3 | Q4: Y4 | R4: Y5
A5: Total revenue | B5: ='Model - Conservative'!B15 | C5: ='Model - Conservative'!C15 | D5: ='Model - Conservative'!D15 | E5: ='Model - Conservative'!E15 | F5: ='Model - Conservative'!F15 | H5: ='Model - Base'!B15 | I5: ='Model - Base'!C15 | J5: ='Model - Base'!D15 | K5: ='Model - Base'!E15 | L5: ='Model - Base'!F15 | N5: ='Model - Ambitious'!B15 | O5: ='Model - Ambitious'!C15 | P5: ='Model - Ambitious'!D15 | Q5: ='Model - Ambitious'!E15 | R5: ='Model - Ambitious'!F15
A6: Working-capital bridge drawn | B6: ='Model - Conservative'!B14 | C6: ='Model - Conservative'!C14 | D6: ='Model - Conservative'!D14 | E6: ='Model - Conservative'!E14 | F6: ='Model - Conservative'!F14 | H6: ='Model - Base'!B14 | I6: ='Model - Base'!C14 | J6: ='Model - Base'!D14 | K6: ='Model - Base'!E14 | L6: ='Model - Base'!F14 | N6: ='Model - Ambitious'!B14 | O6: ='Model - Ambitious'!C14 | P6: ='Model - Ambitious'!D14 | Q6: ='Model - Ambitious'!E14 | R6: ='Model - Ambitious'!F14
A7: Operating result excl. bridge | B7: ='Model - Conservative'!B46 | C7: ='Model - Conservative'!C46 | D7: ='Model - Conservative'!D46 | E7: ='Model - Conservative'!E46 | F7: ='Model - Conservative'!F46 | H7: ='Model - Base'!B46 | I7: ='Model - Base'!C46 | J7: ='Model - Base'!D46 | K7: ='Model - Base'!E46 | L7: ='Model - Base'!F46 | N7: ='Model - Ambitious'!B46 | O7: ='Model - Ambitious'!C46 | P7: ='Model - Ambitious'!D46 | Q7: ='Model - Ambitious'!E46 | R7: ='Model - Ambitious'!F46
A8: Personnel cost | B8: ='Model - Conservative'!B29 | C8: ='Model - Conservative'!C29 | D8: ='Model - Conservative'!D29 | E8: ='Model - Conservative'!E29 | F8: ='Model - Conservative'!F29 | H8: ='Model - Base'!B29 | I8: ='Model - Base'!C29 | J8: ='Model - Base'!D29 | K8: ='Model - Base'!E29 | L8: ='Model - Base'!F29 | N8: ='Model - Ambitious'!B29 | O8: ='Model - Ambitious'!C29 | P8: ='Model - Ambitious'!D29 | Q8: ='Model - Ambitious'!E29 | R8: ='Model - Ambitious'!F29
A9: Total FTE | B9: ='Model - Conservative'!B44 | C9: ='Model - Conservative'!C44 | D9: ='Model - Conservative'!D44 | E9: ='Model - Conservative'!E44 | F9: ='Model - Conservative'!F44 | H9: ='Model - Base'!B44 | I9: ='Model - Base'!C44 | J9: ='Model - Base'!D44 | K9: ='Model - Base'!E44 | L9: ='Model - Base'!F44 | N9: ='Model - Ambitious'!B44 | O9: ='Model - Ambitious'!C44 | P9: ='Model - Ambitious'!D44 | Q9: ='Model - Ambitious'!E44 | R9: ='Model - Ambitious'!F44
A10: Personnel as % of revenue | B10: ='Model - Conservative'!B45 | C10: ='Model - Conservative'!C45 | D10: ='Model - Conservative'!D45 | E10: ='Model - Conservative'!E45 | F10: ='Model - Conservative'!F45 | H10: ='Model - Base'!B45 | I10: ='Model - Base'!C45 | J10: ='Model - Base'!D45 | K10: ='Model - Base'!E45 | L10: ='Model - Base'!F45 | N10: ='Model - Ambitious'!B45 | O10: ='Model - Ambitious'!C45 | P10: ='Model - Ambitious'!D45 | Q10: ='Model - Ambitious'!E45 | R10: ='Model - Ambitious'!F45
A11: New-initiative revenue (lib+cert+B2B) | B11: ='Model - Conservative'!B42 | C11: ='Model - Conservative'!C42 | D11: ='Model - Conservative'!D42 | E11: ='Model - Conservative'!E42 | F11: ='Model - Conservative'!F42 | H11: ='Model - Base'!B42 | I11: ='Model - Base'!C42 | J11: ='Model - Base'!D42 | K11: ='Model - Base'!E42 | L11: ='Model - Base'!F42 | N11: ='Model - Ambitious'!B42 | O11: ='Model - Ambitious'!C42 | P11: ='Model - Ambitious'!D42 | Q11: ='Model - Ambitious'!E42 | R11: ='Model - Ambitious'!F42
A12: New-initiative cost | B12: ='Model - Conservative'!B43 | C12: ='Model - Conservative'!C43 | D12: ='Model - Conservative'!D43 | E12: ='Model - Conservative'!E43 | F12: ='Model - Conservative'!F43 | H12: ='Model - Base'!B43 | I12: ='Model - Base'!C43 | J12: ='Model - Base'!D43 | K12: ='Model - Base'!E43 | L12: ='Model - Base'!F43 | N12: ='Model - Ambitious'!B43 | O12: ='Model - Ambitious'!C43 | P12: ='Model - Ambitious'!D43 | Q12: ='Model - Ambitious'!E43 | R12: ='Model - Ambitious'!F43
A13: Total costs (direct + operating) | B13: ='Model - Conservative'!B22+'Model - Conservative'!B32 | C13: ='Model - Conservative'!C22+'Model - Conservative'!C32 | D13: ='Model - Conservative'!D22+'Model - Conservative'!D32 | E13: ='Model - Conservative'!E22+'Model - Conservative'!E32 | F13: ='Model - Conservative'!F22+'Model - Conservative'!F32 | H13: ='Model - Base'!B22+'Model - Base'!B32 | I13: ='Model - Base'!C22+'Model - Base'!C32 | J13: ='Model - Base'!D22+'Model - Base'!D32 | K13: ='Model - Base'!E22+'Model - Base'!E32 | L13: ='Model - Base'!F22+'Model - Base'!F32 | N13: ='Model - Ambitious'!B22+'Model - Ambitious'!B32 | O13: ='Model - Ambitious'!C22+'Model - Ambitious'!C32 | P13: ='Model - Ambitious'!D22+'Model - Ambitious'!D32 | Q13: ='Model - Ambitious'!E22+'Model - Ambitious'!E32 | R13: ='Model - Ambitious'!F22+'Model - Ambitious'!F32
A14: Net surplus / (deficit) | B14: ='Model - Conservative'!B36 | C14: ='Model - Conservative'!C36 | D14: ='Model - Conservative'!D36 | E14: ='Model - Conservative'!E36 | F14: ='Model - Conservative'!F36 | H14: ='Model - Base'!B36 | I14: ='Model - Base'!C36 | J14: ='Model - Base'!D36 | K14: ='Model - Base'!E36 | L14: ='Model - Base'!F36 | N14: ='Model - Ambitious'!B36 | O14: ='Model - Ambitious'!C36 | P14: ='Model - Ambitious'!D36 | Q14: ='Model - Ambitious'!E36 | R14: ='Model - Ambitious'!F36
A15: Cumulative surplus / (deficit) | B15: ='Model - Conservative'!B37 | C15: ='Model - Conservative'!C37 | D15: ='Model - Conservative'!D37 | E15: ='Model - Conservative'!E37 | F15: ='Model - Conservative'!F37 | H15: ='Model - Base'!B37 | I15: ='Model - Base'!C37 | J15: ='Model - Base'!D37 | K15: ='Model - Base'!E37 | L15: ='Model - Base'!F37 | N15: ='Model - Ambitious'!B37 | O15: ='Model - Ambitious'!C37 | P15: ='Model - Ambitious'!D37 | Q15: ='Model - Ambitious'!E37 | R15: ='Model - Ambitious'!F37
A16: Mission-funding reliance | B16: ='Model - Conservative'!B40 | C16: ='Model - Conservative'!C40 | D16: ='Model - Conservative'!D40 | E16: ='Model - Conservative'!E40 | F16: ='Model - Conservative'!F40 | H16: ='Model - Base'!B40 | I16: ='Model - Base'!C40 | J16: ='Model - Base'!D40 | K16: ='Model - Base'!E40 | L16: ='Model - Base'!F40 | N16: ='Model - Ambitious'!B40 | O16: ='Model - Ambitious'!C40 | P16: ='Model - Ambitious'!D40 | Q16: ='Model - Ambitious'!E40 | R16: ='Model - Ambitious'!F40
A18: Reading the model
A19: • Conservative stays volunteer-tiny (≤0.65 FTE) and net-positive every year — no bridge needed.
A20: • Base (Commercial Engine path) needs a €170k working-capital bridge drawn Y1–Y4 (50/80/10/30). The underlying operating business reaches break-even at Y3; with the bridge every year is net-positive and Y5 produces a genuine €35k surplus.
A21: • Ambitious needs a €115k bridge across Y1–Y2 only; self-sustaining from Y3 and produces a €432k surplus by Y5.
A22: • The Y4 bridge draw (€30k in Base) is larger than Y3's because Y4 carries BOTH the operating dip (team scales ahead of commercial ramp) AND the first year of corporation tax (commercial surplus crosses the €45k exemption). The bridge smooths both.
A23: • 'Operating result excl. bridge' (memo line) shows the underlying business honestly: loss-making Y1–Y4, break-even Y3, surplus Y5. The bridge is the explicit instrument that funds that gap.
A24: • Personnel runs ~50–62% of revenue early, settling to ~40–49% by Y5 — normal for a service/community nonprofit.

Sheet Research & Benchmarks
A1: Research & Benchmarks — what's reasonable, with sources
A2: Used to ground the assumptions and salary costs. Every row links to its primary source.
A4: Source | B4: Figure | C4: Why it matters | D4: Link
A5: Salaries & staffing
A6: Laravel-Entwickler — Laravel salary guide | B6: Germany: junior €30–45k, mid €50–65k, senior €70–90k (avg ~€55k) | C6: Anchors the Engineering role costs. All-in cost = these gross figures × ~1.22 employer overhead. | D6: https://www.laravel-entwickler.de/en/laravel-developer-salary-a-comprehensive-guide/
A7: Glassdoor — PHP Laravel Developer salary Germany | B7: Avg €67,000 (range €56,500–€70,000) | C7: Cross-check for senior/mid engineering gross salaries in Germany. | D7: https://www.glassdoor.com/Salaries/germany-laravel-php-developer-salary-SRCH_IL.0,7_IN96_KO8,29.htm
A8: GermanTechJobs — Laravel salary Germany | B8: Avg €58,000 / median €57,500 | C8: Independent market aggregate for Laravel roles in Germany. | D8: https://germantechjobs.de/en/salaries/Laravel/all/all
A9: PayScale — Program Manager, Non-Profit (Germany) | B9: Avg €49,974 (early €42k, mid €58k) | C9: Anchors Community Manager / Programme Lead costs in the nonprofit sector. | D9: https://www.payscale.com/research/DE/Job=Program_Manager%2C_Non-Profit_Organization/Salary
A10: SalaryExpert — Non-Profit Director (Germany) | B10: Avg €42,646 (entry €31,696) | C10: Reference for fundraising/operations leadership roles; nonprofit-sector ceiling. | D10: https://www.salaryexpert.com/salary/job/non-profit-director/germany
A11: SalaryExplorer — Fundraising & Non-Profit (Germany) | B11: Median €2,660/mo (~€32k), avg €2,810/mo, up to €5,670/mo (~€68k) | C11: Fundraising/Grants Lead and Partnerships Manager salary band (nonprofit field). | D11: http://www.salaryexplorer.com/salary-survey.php?loc=81&loctype=1&job=5&jobtype=1
A12: EngageAnywhere — Employee costs in Germany | B12: Employer overhead ~21–23% (Arbeitgeberanteil) | C12: Drives the gross × 1.22 multiplier used for all-in role costs. Pension 9.3%, health 7.3%, unemployment 1.3%, care 1.525%. | D12: https://engageanywhere.com/blog/calculating-employee-costs-in-germany-step-by-step/
A13: FMC Group — Total cost of employment in Germany | B13: Total employer cost 20–26% above gross | C13: Confirms the all-in multiplier band; notes social-security contribution caps flatten senior costs. | D13: https://fmcgroup.com/employment-cost-germany/
A14: German donations
A15: IW Köln — Fast jeder zweite Deutsche spendet | B15: ~€415/donor/yr avg (median ~€300) | C15: German donors give less per head than the global average. Model uses €45–125/yr per recurring donor. Note: site may return HTTP 401 to bots/HEAD; opens normally in a browser. | D15: https://www.iwkoeln.de/studien/dominik-h-enste-jennifer-potthoff-fast-jeder-zweite-deutsche-spendet.html
A16: DIW SOEPpapers — Spenden in Deutschland | B16: Median €200→€300 (2009–2017) | C16: Methodology detail behind German donation-volume estimates. | D16: https://www.diw.de/documents/publikationen/73/diw_01.c.738864.de/diw_sp1074.pdf
A17: World Giving Report (CAF / Maecenata) | B17: 46–49% of Germans donate (global 61–64%) | C17: Germany is a low-giving culture; transparency lever for fundraising. | D17: https://www.maecenata.eu/2026/06/03/world-giving-report-2025-deutschland-spendet-weiterhin-unterdurchschnittlich
A18: Giving in Germany Report 2025 (CAF / Maecenata) | B18: 0.39% of income donated; rank 100/101 | C18: Companion country report; useful for funder conversations. | D18: https://www.maecenata.eu/2025/07/23/giving-in-germany-report-2025-deutschland-zaehlt-zu-den-schlusslichtern-beim-spenden-weltweit/
A19: DZI — Spendenstatistik | B19: €5.1bn vs €10.3bn volume estimates | C19: Why different surveys disagree. | D19: https://www.dzi.de/spendenberatung/spendenauskunfte-und-information/spendenstatistik/
A20: Recurring giving
A21: Neon One — Recurring Giving Statistics 2026 | B21: ~$938 / recurring donor / yr | C21: Upper bound for engaged recurring donors (US); Ambitious scenario only. | D21: https://neonone.com/resources/blog/recurring-giving-statistics/
A22: Qgiv — Fundraising Statistics | B22: Recurring donors avg $287/yr (2022) | C22: Sanity-check band for recurring donation assumptions. | D22: https://www.qgiv.com/blog/fundraising-statistics/
A23: EU grants
A24: CERV Programme 2026 — guide (global-disruption) | B24: €75k–€500k+; 90% funded; transnational | C24: Civic engagement, inclusion, digital participation. Realistic first win year 2–3 with an NGO partner. | D24: https://global-disruption.com/eu-calls/cerv/index.html
A25: EUFundingPortal — CERV calls | B25: Town twinning €8.5k–€50.7k; civic min €75k | C25: Concrete call budgets and per-project ranges. | D25: https://eufundingportal.eu/programme/cerv/
A26: EUFundingPortal — CERV Programme overview | B26: Per-call budgets and deadlines | C26: Companion overview with current open calls. | D26: https://eufundingportal.eu/cerv-programme/
A27: Creative Europe — calls (EUFundingPortal) | B27: Projects up to €500k | C27: Culture + social-cohesion strand; 'belonging through play' maps to social-resilience objective. | D27: https://eufundingportal.eu/programme/creative-europe/
A28: Culture Action Europe — next Creative Europe / AgoraEU | B28: €8.6bn proposed 2028–2034 (€1.8bn culture) | C28: Forward look on EU culture funding. | D28: https://cultureactioneurope.org/news/proposed-e8-6-billion-for-culture-and-democracy-in-the-next-eu-budget/
A29: Culture Action Europe — leaked next programme detail | B29: Strand structure + social conditionality | C29: Deeper detail on the next Creative Europe strands. | D29: https://cultureactioneurope.org/news/the-next-creative-europe-programme-has-been-leaked/
A30: Erasmus+ — overview (EUFundingPortal) | B30: Inclusion, diversity & digital transformation | C30: Youth / non-formal-education angle; programmatic grants tied to community events. | D30: https://eufundingportal.eu/erasmus-plus/
A31: German foundations
A32: Aktion Mensch — Förderung | B32: Inclusion project grants (varies) | C32: Major German lottery-funded grantmaker; application via DIAS; nachrangig to public funds. Many calls paused. | D32: https://www.aktion-mensch.de/foerderung
A33: reflecta Fördermittelkompass — Social Support Germany | B33: Project grants typically €2k–€50k | C33: Aggregates ESF+, BMFSFJ, BMAS, Aktion Mensch, TV Lottery. Ideal year-1 funding. | D33: https://foerdermittelkompass.reflecta.org/foerderungen/soziales-foerderungen-deutschland?locale=en
A34: Bund.de Förderdatenbank | B34: Federal funding search | C34: Primary search portal for all federal/state funding programmes. | D34: https://www.foerderdatenbank.de/
A35: German tax law
A36: Council on Foundations — Nonprofit Law in Germany | B36: §5(1) Nr.9 KStG; Zweckbetrieb 7% VAT | C36: Purpose-serving revenue exempt from KSt/GewSt; reduced VAT for Zweckbetrieb services. | D36: https://cof.org/content/nonprofit-law-germany
A37: GermanCompanyFormation — Non-Profits in Germany | B37: Commercial surplus taxed above €45,000/yr | C37: Steuerpflichtiger wirtschaftlicher Geschäftsbetrieb vs Zweckbetrieb; drives the tax line. | D37: https://germancompanyformation.com/guides/what-is-non-profit-organizations-in-germany
A38: Liesegang Partner — Tax-Exempt Status for NPOs | B38: gemeinnützige Zwecke (§52 AO) definition | C38: What qualifies as public-benefit; supports e.V. vs gGmbH choice. | D38: https://www.liesegang-partner.com/knowhow/corporate-law/translate-to-englisch-unlocking-tax-benefits-how-non-profits-in-germany-can-achieve-tax-exempt-status
A39: Library of things
A40: Share Shed — Setting Up & Sustaining a LoT | B40: Membership income < full costs in early years | C40: Lending revenue alone doesn't cover rent/staff early on; grants + volunteers + in-kind space needed. Inventory often donated/discounted. | D40: https://www.shareshed.org.uk/wp-content/uploads/2024/12/Setting-Up-and-Sustaining-a-Library-of-Things-FINAL-2.pdf
A41: Shareable — How to start a Library of Things | B41: Subscription + premium-item fees most sustainable | C41: Anchors the library-tier fee model; sliding-scale for affordability. | D41: https://www.shareable.net/how-to/how-to-start-a-library-of-things/
...
